2020-01-27 10:03:08,096 ERROR: Exception on /ct [POST] [in c:\users\marks\local sites\mvr flask database\venv\lib\site-packages\flask\app.py:1780]
Traceback (most recent call last):
  File "c:\users\marks\local sites\mvr flask database\venv\lib\site-packages\flask\app.py", line 2311, in wsgi_app
    response = self.full_dispatch_request()
  File "c:\users\marks\local sites\mvr flask database\venv\lib\site-packages\flask\app.py", line 1834, in full_dispatch_request
    rv = self.handle_user_exception(e)
  File "c:\users\marks\local sites\mvr flask database\venv\lib\site-packages\flask\app.py", line 1737, in handle_user_exception
    reraise(exc_type, exc_value, tb)
  File "c:\users\marks\local sites\mvr flask database\venv\lib\site-packages\flask\_compat.py", line 36, in reraise
    raise value
  File "c:\users\marks\local sites\mvr flask database\venv\lib\site-packages\flask\app.py", line 1832, in full_dispatch_request
    rv = self.dispatch_request()
  File "c:\users\marks\local sites\mvr flask database\venv\lib\site-packages\flask\app.py", line 1818, in dispatch_request
    return self.view_functions[rule.endpoint](**req.view_args)
  File "C:\Users\marks\Local Sites\MVR Flask Database\app\routes.py", line 141, in CT
    return redirect(url_for('ct'))
  File "c:\users\marks\local sites\mvr flask database\venv\lib\site-packages\flask\helpers.py", line 356, in url_for
    return appctx.app.handle_url_build_error(error, endpoint, values)
  File "c:\users\marks\local sites\mvr flask database\venv\lib\site-packages\flask\app.py", line 2080, in handle_url_build_error
    reraise(exc_type, exc_value, tb)
  File "c:\users\marks\local sites\mvr flask database\venv\lib\site-packages\flask\_compat.py", line 36, in reraise
    raise value
  File "c:\users\marks\local sites\mvr flask database\venv\lib\site-packages\flask\helpers.py", line 345, in url_for
    force_external=external)
  File "c:\users\marks\local sites\mvr flask database\venv\lib\site-packages\werkzeug\routing.py", line 2007, in build
    raise BuildError(endpoint, values, method, self)
werkzeug.routing.BuildError: Could not build url for endpoint 'ct'. Did you mean 'ctTable' instead?
2020-01-27 10:08:44,101 ERROR: Exception on /ct [POST] [in c:\users\marks\local sites\mvr flask database\venv\lib\site-packages\flask\app.py:1780]
Traceback (most recent call last):
  File "c:\users\marks\local sites\mvr flask database\venv\lib\site-packages\flask\app.py", line 2311, in wsgi_app
    response = self.full_dispatch_request()
  File "c:\users\marks\local sites\mvr flask database\venv\lib\site-packages\flask\app.py", line 1834, in full_dispatch_request
    rv = self.handle_user_exception(e)
  File "c:\users\marks\local sites\mvr flask database\venv\lib\site-packages\flask\app.py", line 1737, in handle_user_exception
    reraise(exc_type, exc_value, tb)
  File "c:\users\marks\local sites\mvr flask database\venv\lib\site-packages\flask\_compat.py", line 36, in reraise
    raise value
  File "c:\users\marks\local sites\mvr flask database\venv\lib\site-packages\flask\app.py", line 1832, in full_dispatch_request
    rv = self.dispatch_request()
  File "c:\users\marks\local sites\mvr flask database\venv\lib\site-packages\flask\app.py", line 1818, in dispatch_request
    return self.view_functions[rule.endpoint](**req.view_args)
  File "C:\Users\marks\Local Sites\MVR Flask Database\app\routes.py", line 141, in CT
    return redirect(url_for('ct'))
  File "c:\users\marks\local sites\mvr flask database\venv\lib\site-packages\flask\helpers.py", line 356, in url_for
    return appctx.app.handle_url_build_error(error, endpoint, values)
  File "c:\users\marks\local sites\mvr flask database\venv\lib\site-packages\flask\app.py", line 2080, in handle_url_build_error
    reraise(exc_type, exc_value, tb)
  File "c:\users\marks\local sites\mvr flask database\venv\lib\site-packages\flask\_compat.py", line 36, in reraise
    raise value
  File "c:\users\marks\local sites\mvr flask database\venv\lib\site-packages\flask\helpers.py", line 345, in url_for
    force_external=external)
  File "c:\users\marks\local sites\mvr flask database\venv\lib\site-packages\werkzeug\routing.py", line 2007, in build
    raise BuildError(endpoint, values, method, self)
werkzeug.routing.BuildError: Could not build url for endpoint 'ct'. Did you mean 'ctTable' instead?
2020-01-27 10:09:55,654 INFO: MVR Database [in C:\Users\marks\Local Sites\MVR Flask Database\app\__init__.py:49]
2020-01-27 10:15:37,778 INFO: MVR Database [in C:\Users\marks\Local Sites\MVR Flask Database\app\__init__.py:49]
2020-01-27 10:20:19,118 INFO: MVR Database [in C:\Users\marks\Local Sites\MVR Flask Database\app\__init__.py:49]
2020-01-27 10:20:23,810 ERROR: Exception on /invoice [GET] [in c:\users\marks\local sites\mvr flask database\venv\lib\site-packages\flask\app.py:1780]
Traceback (most recent call last):
  File "c:\users\marks\local sites\mvr flask database\venv\lib\site-packages\flask\app.py", line 2311, in wsgi_app
    response = self.full_dispatch_request()
  File "c:\users\marks\local sites\mvr flask database\venv\lib\site-packages\flask\app.py", line 1834, in full_dispatch_request
    rv = self.handle_user_exception(e)
  File "c:\users\marks\local sites\mvr flask database\venv\lib\site-packages\flask\app.py", line 1737, in handle_user_exception
    reraise(exc_type, exc_value, tb)
  File "c:\users\marks\local sites\mvr flask database\venv\lib\site-packages\flask\_compat.py", line 36, in reraise
    raise value
  File "c:\users\marks\local sites\mvr flask database\venv\lib\site-packages\flask\app.py", line 1832, in full_dispatch_request
    rv = self.dispatch_request()
  File "c:\users\marks\local sites\mvr flask database\venv\lib\site-packages\flask\app.py", line 1818, in dispatch_request
    return self.view_functions[rule.endpoint](**req.view_args)
  File "C:\Users\marks\Local Sites\MVR Flask Database\app\routes.py", line 218, in invoice
    return render_template('/invoice.html',  title='New Invoice', report_ct=report_ct)
  File "c:\users\marks\local sites\mvr flask database\venv\lib\site-packages\flask\templating.py", line 134, in render_template
    return _render(ctx.app.jinja_env.get_or_select_template(template_name_or_list),
  File "c:\users\marks\local sites\mvr flask database\venv\lib\site-packages\jinja2\environment.py", line 869, in get_or_select_template
    return self.get_template(template_name_or_list, parent, globals)
  File "c:\users\marks\local sites\mvr flask database\venv\lib\site-packages\jinja2\environment.py", line 830, in get_template
    return self._load_template(name, self.make_globals(globals))
  File "c:\users\marks\local sites\mvr flask database\venv\lib\site-packages\jinja2\environment.py", line 804, in _load_template
    template = self.loader.load(self, name, globals)
  File "c:\users\marks\local sites\mvr flask database\venv\lib\site-packages\jinja2\loaders.py", line 125, in load
    code = environment.compile(source, name, filename)
  File "c:\users\marks\local sites\mvr flask database\venv\lib\site-packages\jinja2\environment.py", line 591, in compile
    self.handle_exception(exc_info, source_hint=source_hint)
  File "c:\users\marks\local sites\mvr flask database\venv\lib\site-packages\jinja2\environment.py", line 780, in handle_exception
    reraise(exc_type, exc_value, tb)
  File "c:\users\marks\local sites\mvr flask database\venv\lib\site-packages\jinja2\_compat.py", line 37, in reraise
    raise value.with_traceback(tb)
  File "C:\Users\marks\Local Sites\MVR Flask Database\app\templates\invoice.html", line 48, in template
    {% endfor %}
  File "c:\users\marks\local sites\mvr flask database\venv\lib\site-packages\jinja2\environment.py", line 497, in _parse
    return Parser(self, source, name, encode_filename(filename)).parse()
  File "c:\users\marks\local sites\mvr flask database\venv\lib\site-packages\jinja2\parser.py", line 901, in parse
    result = nodes.Template(self.subparse(), lineno=1)
  File "c:\users\marks\local sites\mvr flask database\venv\lib\site-packages\jinja2\parser.py", line 883, in subparse
    rv = self.parse_statement()
  File "c:\users\marks\local sites\mvr flask database\venv\lib\site-packages\jinja2\parser.py", line 130, in parse_statement
    return getattr(self, 'parse_' + self.stream.current.value)()
  File "c:\users\marks\local sites\mvr flask database\venv\lib\site-packages\jinja2\parser.py", line 268, in parse_block
    node.body = self.parse_statements(('name:endblock',), drop_needle=True)
  File "c:\users\marks\local sites\mvr flask database\venv\lib\site-packages\jinja2\parser.py", line 170, in parse_statements
    self.fail_eof(end_tokens)
  File "c:\users\marks\local sites\mvr flask database\venv\lib\site-packages\jinja2\parser.py", line 104, in fail_eof
    return self._fail_ut_eof(None, stack, lineno)
  File "c:\users\marks\local sites\mvr flask database\venv\lib\site-packages\jinja2\parser.py", line 90, in _fail_ut_eof
    self.fail(' '.join(message), lineno)
  File "c:\users\marks\local sites\mvr flask database\venv\lib\site-packages\jinja2\parser.py", line 59, in fail
    raise exc(msg, lineno, self.name, self.filename)
jinja2.exceptions.TemplateSyntaxError: Unexpected end of template. Jinja was looking for the following tags: 'endblock'. The innermost block that needs to be closed is 'block'.
2020-01-27 10:20:51,902 INFO: MVR Database [in C:\Users\marks\Local Sites\MVR Flask Database\app\__init__.py:49]
