2019-08-13 13:00:17,694 ERROR: Exception on /newdoc [POST] [in c:\users\mark\local sites\mvr database\mvr-database\venv\lib\site-packages\flask\app.py:1780]
Traceback (most recent call last):
  File "c:\users\mark\local sites\mvr database\mvr-database\venv\lib\site-packages\flask\app.py", line 2311, in wsgi_app
    response = self.full_dispatch_request()
  File "c:\users\mark\local sites\mvr database\mvr-database\venv\lib\site-packages\flask\app.py", line 1834, in full_dispatch_request
    rv = self.handle_user_exception(e)
  File "c:\users\mark\local sites\mvr database\mvr-database\venv\lib\site-packages\flask\app.py", line 1737, in handle_user_exception
    reraise(exc_type, exc_value, tb)
  File "c:\users\mark\local sites\mvr database\mvr-database\venv\lib\site-packages\flask\_compat.py", line 36, in reraise
    raise value
  File "c:\users\mark\local sites\mvr database\mvr-database\venv\lib\site-packages\flask\app.py", line 1832, in full_dispatch_request
    rv = self.dispatch_request()
  File "c:\users\mark\local sites\mvr database\mvr-database\venv\lib\site-packages\flask\app.py", line 1818, in dispatch_request
    return self.view_functions[rule.endpoint](**req.view_args)
  File "C:\Users\Mark\Local Sites\MVR database\MVR-Database\app\routes.py", line 131, in newDoc
    doctor = Doctor(clinicName=form.clinic.data, clinicSerialNum=form.clinic.value, first=form.first.data, middle=form.middle.data, last=form.last.data, phone=form.phone.data, email=form.email.data, note=form.note.data, doctorSerialNum=randomStringDigits(8))
AttributeError: 'SelectField' object has no attribute 'value'
2019-08-13 13:09:24,709 INFO: MVR Database [in C:\Users\Mark\Local Sites\MVR database\MVR-Database\app\__init__.py:47]
2019-08-13 13:11:47,436 INFO: MVR Database [in C:\Users\Mark\Local Sites\MVR database\MVR-Database\app\__init__.py:47]
2019-08-13 13:14:10,994 INFO: MVR Database [in C:\Users\Mark\Local Sites\MVR database\MVR-Database\app\__init__.py:47]
2019-08-15 12:50:08,452 INFO: MVR Database [in C:\Users\Mark\Local Sites\MVR database\MVR-Database\app\__init__.py:47]
2019-08-15 12:55:43,250 INFO: MVR Database [in C:\Users\Mark\Local Sites\MVR database\MVR-Database\app\__init__.py:47]
2019-08-15 13:03:17,352 INFO: MVR Database [in C:\Users\Mark\Local Sites\MVR database\MVR-Database\app\__init__.py:47]
2019-08-15 13:21:43,912 INFO: MVR Database [in C:\Users\Mark\Local Sites\MVR database\MVR-Database\app\__init__.py:47]
2019-08-15 13:32:40,890 INFO: MVR Database [in C:\Users\Mark\Local Sites\MVR database\MVR-Database\app\__init__.py:47]
2019-08-15 13:33:24,758 ERROR: Exception on /ultrasound [POST] [in c:\users\mark\local sites\mvr database\mvr-database\venv\lib\site-packages\flask\app.py:1780]
Traceback (most recent call last):
  File "c:\users\mark\local sites\mvr database\mvr-database\venv\lib\site-packages\flask\app.py", line 2311, in wsgi_app
    response = self.full_dispatch_request()
  File "c:\users\mark\local sites\mvr database\mvr-database\venv\lib\site-packages\flask\app.py", line 1834, in full_dispatch_request
    rv = self.handle_user_exception(e)
  File "c:\users\mark\local sites\mvr database\mvr-database\venv\lib\site-packages\flask\app.py", line 1737, in handle_user_exception
    reraise(exc_type, exc_value, tb)
  File "c:\users\mark\local sites\mvr database\mvr-database\venv\lib\site-packages\flask\_compat.py", line 36, in reraise
    raise value
  File "c:\users\mark\local sites\mvr database\mvr-database\venv\lib\site-packages\flask\app.py", line 1832, in full_dispatch_request
    rv = self.dispatch_request()
  File "c:\users\mark\local sites\mvr database\mvr-database\venv\lib\site-packages\flask\app.py", line 1818, in dispatch_request
    return self.view_functions[rule.endpoint](**req.view_args)
  File "C:\Users\Mark\Local Sites\MVR database\MVR-Database\app\routes.py", line 102, in ultrasound
    print(clinicDoctor)
NameError: name 'clinicDoctor' is not defined
2019-08-15 13:37:29,015 INFO: MVR Database [in C:\Users\Mark\Local Sites\MVR database\MVR-Database\app\__init__.py:47]
2019-08-15 13:37:37,319 ERROR: Exception on /ultrasound [POST] [in c:\users\mark\local sites\mvr database\mvr-database\venv\lib\site-packages\flask\app.py:1780]
Traceback (most recent call last):
  File "c:\users\mark\local sites\mvr database\mvr-database\venv\lib\site-packages\flask\app.py", line 2311, in wsgi_app
    response = self.full_dispatch_request()
  File "c:\users\mark\local sites\mvr database\mvr-database\venv\lib\site-packages\flask\app.py", line 1834, in full_dispatch_request
    rv = self.handle_user_exception(e)
  File "c:\users\mark\local sites\mvr database\mvr-database\venv\lib\site-packages\flask\app.py", line 1737, in handle_user_exception
    reraise(exc_type, exc_value, tb)
  File "c:\users\mark\local sites\mvr database\mvr-database\venv\lib\site-packages\flask\_compat.py", line 36, in reraise
    raise value
  File "c:\users\mark\local sites\mvr database\mvr-database\venv\lib\site-packages\flask\app.py", line 1832, in full_dispatch_request
    rv = self.dispatch_request()
  File "c:\users\mark\local sites\mvr database\mvr-database\venv\lib\site-packages\flask\app.py", line 1818, in dispatch_request
    return self.view_functions[rule.endpoint](**req.view_args)
  File "C:\Users\Mark\Local Sites\MVR database\MVR-Database\app\routes.py", line 103, in ultrasound
    ultrasound = Report_US(doctor=doctorData[0], docSerialNum=doctorData[1], clinicName=clinicData[0], clinicSerialNum=clinicData[1], patient=form.patient.data, owner=form.owner.data, species=form.species.data, breed=form.breed.data, sexPatient=form.sex.data, agePetient=form.age.data, clinicalHistory=form.age.data, SF_Liver=form.liver.data, SF_Spleen=form.spleen.data, SF_Stomach=form.stomach.data, SF_Pancreas=form.pancreas.data, SF_Intestines=form.intestines.data, SF_Adrenals=form.adrenals.data, SF_LKidney=form.lKidney.data, SF_RKidney=form.rKidney.data, SF_Bladder=form.bladder.data, SF_Sublum=form.sublum.data, SF_Prostate=form.prostate.data, SF_Uterus=form.uterus.data, Conclusions_ALL=form.conclusions.data, FINDAS_ALL=form.findings.data, date=form.date.data)
  File "<string>", line 4, in __init__
  File "c:\users\mark\local sites\mvr database\mvr-database\venv\lib\site-packages\sqlalchemy\orm\state.py", line 441, in _initialize_instance
    manager.dispatch.init_failure(self, args, kwargs)
  File "c:\users\mark\local sites\mvr database\mvr-database\venv\lib\site-packages\sqlalchemy\util\langhelpers.py", line 68, in __exit__
    compat.reraise(exc_type, exc_value, exc_tb)
  File "c:\users\mark\local sites\mvr database\mvr-database\venv\lib\site-packages\sqlalchemy\util\compat.py", line 154, in reraise
    raise value
  File "c:\users\mark\local sites\mvr database\mvr-database\venv\lib\site-packages\sqlalchemy\orm\state.py", line 438, in _initialize_instance
    return manager.original_init(*mixed[1:], **kwargs)
  File "c:\users\mark\local sites\mvr database\mvr-database\venv\lib\site-packages\sqlalchemy\ext\declarative\base.py", line 840, in _declarative_constructor
    "%r is an invalid keyword argument for %s" % (k, cls_.__name__)
TypeError: 'agePetient' is an invalid keyword argument for Report_US
2019-08-15 13:45:03,040 INFO: MVR Database [in C:\Users\Mark\Local Sites\MVR database\MVR-Database\app\__init__.py:47]
2019-08-15 13:45:30,088 INFO: MVR Database [in C:\Users\Mark\Local Sites\MVR database\MVR-Database\app\__init__.py:47]
2019-08-15 13:49:03,086 INFO: MVR Database [in C:\Users\Mark\Local Sites\MVR database\MVR-Database\app\__init__.py:47]
2019-08-15 13:49:38,733 INFO: MVR Database [in C:\Users\Mark\Local Sites\MVR database\MVR-Database\app\__init__.py:47]
2019-08-15 15:12:09,282 INFO: MVR Database [in C:\Users\Mark\Local Sites\MVR database\MVR-Database\app\__init__.py:47]
2019-08-15 15:12:39,756 INFO: MVR Database [in C:\Users\Mark\Local Sites\MVR database\MVR-Database\app\__init__.py:47]
2019-08-15 15:15:05,469 INFO: MVR Database [in C:\Users\Mark\Local Sites\MVR database\MVR-Database\app\__init__.py:47]
2019-08-15 15:21:45,664 INFO: MVR Database [in C:\Users\Mark\Local Sites\MVR database\MVR-Database\app\__init__.py:47]
2019-08-15 15:21:50,110 INFO: MVR Database [in C:\Users\Mark\Local Sites\MVR database\MVR-Database\app\__init__.py:47]
2019-08-15 15:27:41,155 INFO: MVR Database [in C:\Users\Mark\Local Sites\MVR database\MVR-Database\app\__init__.py:47]
2019-08-15 15:27:48,237 INFO: MVR Database [in C:\Users\Mark\Local Sites\MVR database\MVR-Database\app\__init__.py:47]
2019-08-15 15:29:53,032 INFO: MVR Database [in C:\Users\Mark\Local Sites\MVR database\MVR-Database\app\__init__.py:47]
2019-08-15 15:32:49,702 INFO: MVR Database [in C:\Users\Mark\Local Sites\MVR database\MVR-Database\app\__init__.py:47]
2019-08-15 15:33:59,177 INFO: MVR Database [in C:\Users\Mark\Local Sites\MVR database\MVR-Database\app\__init__.py:47]
2019-08-15 15:38:46,447 INFO: MVR Database [in C:\Users\Mark\Local Sites\MVR database\MVR-Database\app\__init__.py:47]
2019-08-15 15:39:40,606 INFO: MVR Database [in C:\Users\Mark\Local Sites\MVR database\MVR-Database\app\__init__.py:47]
