2020-03-10 11:54:09,697 ERROR: Exception on /edit [GET] [in c:\users\marks\local sites\mvr flask database\venv\lib\site-packages\flask\app.py:1780]
Traceback (most recent call last):
  File "c:\users\marks\local sites\mvr flask database\venv\lib\site-packages\flask\app.py", line 2311, in wsgi_app
    response = self.full_dispatch_request()
  File "c:\users\marks\local sites\mvr flask database\venv\lib\site-packages\flask\app.py", line 1835, in full_dispatch_request
    return self.finalize_request(rv)
  File "c:\users\marks\local sites\mvr flask database\venv\lib\site-packages\flask\app.py", line 1850, in finalize_request
    response = self.make_response(rv)
  File "c:\users\marks\local sites\mvr flask database\venv\lib\site-packages\flask\app.py", line 1976, in make_response
    'The view function did not return a valid response. The'
TypeError: The view function did not return a valid response. The function either returned None or ended without a return statement.
2020-03-10 11:58:03,356 INFO: MVR Database [in C:\Users\marks\Local Sites\MVR Flask Database\app\__init__.py:49]
2020-03-10 11:58:36,103 ERROR: Exception on /edit [GET] [in c:\users\marks\local sites\mvr flask database\venv\lib\site-packages\flask\app.py:1780]
Traceback (most recent call last):
  File "c:\users\marks\local sites\mvr flask database\venv\lib\site-packages\flask\app.py", line 2311, in wsgi_app
    response = self.full_dispatch_request()
  File "c:\users\marks\local sites\mvr flask database\venv\lib\site-packages\flask\app.py", line 1834, in full_dispatch_request
    rv = self.handle_user_exception(e)
  File "c:\users\marks\local sites\mvr flask database\venv\lib\site-packages\flask\app.py", line 1737, in handle_user_exception
    reraise(exc_type, exc_value, tb)
  File "c:\users\marks\local sites\mvr flask database\venv\lib\site-packages\flask\_compat.py", line 36, in reraise
    raise value
  File "c:\users\marks\local sites\mvr flask database\venv\lib\site-packages\flask\app.py", line 1832, in full_dispatch_request
    rv = self.dispatch_request()
  File "c:\users\marks\local sites\mvr flask database\venv\lib\site-packages\flask\app.py", line 1818, in dispatch_request
    return self.view_functions[rule.endpoint](**req.view_args)
  File "C:\Users\marks\Local Sites\MVR Flask Database\app\routes.py", line 320, in editEntry
    return editCT(entryID)
  File "C:\Users\marks\Local Sites\MVR Flask Database\app\editRoute.py", line 255, in editCT
    if form.validate_on_submit():
AttributeError: 'Report_CT' object has no attribute 'validate_on_submit'
2020-03-10 12:00:21,188 INFO: MVR Database [in C:\Users\marks\Local Sites\MVR Flask Database\app\__init__.py:49]
2020-03-10 12:00:21,992 ERROR: Exception on /edit [GET] [in c:\users\marks\local sites\mvr flask database\venv\lib\site-packages\flask\app.py:1780]
Traceback (most recent call last):
  File "c:\users\marks\local sites\mvr flask database\venv\lib\site-packages\flask\app.py", line 2311, in wsgi_app
    response = self.full_dispatch_request()
  File "c:\users\marks\local sites\mvr flask database\venv\lib\site-packages\flask\app.py", line 1834, in full_dispatch_request
    rv = self.handle_user_exception(e)
  File "c:\users\marks\local sites\mvr flask database\venv\lib\site-packages\flask\app.py", line 1737, in handle_user_exception
    reraise(exc_type, exc_value, tb)
  File "c:\users\marks\local sites\mvr flask database\venv\lib\site-packages\flask\_compat.py", line 36, in reraise
    raise value
  File "c:\users\marks\local sites\mvr flask database\venv\lib\site-packages\flask\app.py", line 1832, in full_dispatch_request
    rv = self.dispatch_request()
  File "c:\users\marks\local sites\mvr flask database\venv\lib\site-packages\flask\app.py", line 1818, in dispatch_request
    return self.view_functions[rule.endpoint](**req.view_args)
  File "C:\Users\marks\Local Sites\MVR Flask Database\app\routes.py", line 320, in editEntry
    return editCT(entryID)
  File "C:\Users\marks\Local Sites\MVR Flask Database\app\editRoute.py", line 255, in editCT
    if form.validate_on_submit():
AttributeError: 'Report_CT' object has no attribute 'validate_on_submit'
2020-03-10 12:02:03,787 INFO: MVR Database [in C:\Users\marks\Local Sites\MVR Flask Database\app\__init__.py:49]
2020-03-10 12:14:11,012 INFO: MVR Database [in C:\Users\marks\Local Sites\MVR Flask Database\app\__init__.py:49]
2020-03-10 12:15:39,900 INFO: MVR Database [in C:\Users\marks\Local Sites\MVR Flask Database\app\__init__.py:49]
2020-03-10 12:16:34,243 INFO: MVR Database [in C:\Users\marks\Local Sites\MVR Flask Database\app\__init__.py:49]
2020-03-10 12:16:36,504 INFO: MVR Database [in C:\Users\marks\Local Sites\MVR Flask Database\app\__init__.py:49]
2020-03-10 12:16:38,743 INFO: MVR Database [in C:\Users\marks\Local Sites\MVR Flask Database\app\__init__.py:49]
2020-03-10 12:16:48,028 ERROR: Exception on /edit [GET] [in c:\users\marks\local sites\mvr flask database\venv\lib\site-packages\flask\app.py:1780]
Traceback (most recent call last):
  File "c:\users\marks\local sites\mvr flask database\venv\lib\site-packages\flask\app.py", line 2311, in wsgi_app
    response = self.full_dispatch_request()
  File "c:\users\marks\local sites\mvr flask database\venv\lib\site-packages\flask\app.py", line 1835, in full_dispatch_request
    return self.finalize_request(rv)
  File "c:\users\marks\local sites\mvr flask database\venv\lib\site-packages\flask\app.py", line 1850, in finalize_request
    response = self.make_response(rv)
  File "c:\users\marks\local sites\mvr flask database\venv\lib\site-packages\flask\app.py", line 1976, in make_response
    'The view function did not return a valid response. The'
TypeError: The view function did not return a valid response. The function either returned None or ended without a return statement.
2020-03-10 12:17:21,666 INFO: MVR Database [in C:\Users\marks\Local Sites\MVR Flask Database\app\__init__.py:49]
2020-03-10 12:19:29,910 INFO: MVR Database [in C:\Users\marks\Local Sites\MVR Flask Database\app\__init__.py:49]
2020-03-10 12:22:02,549 INFO: MVR Database [in C:\Users\marks\Local Sites\MVR Flask Database\app\__init__.py:49]
2020-03-10 12:22:09,546 ERROR: Exception on /edit [GET] [in c:\users\marks\local sites\mvr flask database\venv\lib\site-packages\flask\app.py:1780]
Traceback (most recent call last):
  File "c:\users\marks\local sites\mvr flask database\venv\lib\site-packages\flask\app.py", line 2311, in wsgi_app
    response = self.full_dispatch_request()
  File "c:\users\marks\local sites\mvr flask database\venv\lib\site-packages\flask\app.py", line 1834, in full_dispatch_request
    rv = self.handle_user_exception(e)
  File "c:\users\marks\local sites\mvr flask database\venv\lib\site-packages\flask\app.py", line 1737, in handle_user_exception
    reraise(exc_type, exc_value, tb)
  File "c:\users\marks\local sites\mvr flask database\venv\lib\site-packages\flask\_compat.py", line 36, in reraise
    raise value
  File "c:\users\marks\local sites\mvr flask database\venv\lib\site-packages\flask\app.py", line 1832, in full_dispatch_request
    rv = self.dispatch_request()
  File "c:\users\marks\local sites\mvr flask database\venv\lib\site-packages\flask\app.py", line 1818, in dispatch_request
    return self.view_functions[rule.endpoint](**req.view_args)
  File "C:\Users\marks\Local Sites\MVR Flask Database\app\routes.py", line 306, in editEntry
    return editService(entryID)
  File "C:\Users\marks\Local Sites\MVR Flask Database\app\editRoute.py", line 181, in editService
    return render_template('newService.html.html', title='Edit Service', entry=formEntry, form=form)
  File "c:\users\marks\local sites\mvr flask database\venv\lib\site-packages\flask\templating.py", line 134, in render_template
    return _render(ctx.app.jinja_env.get_or_select_template(template_name_or_list),
  File "c:\users\marks\local sites\mvr flask database\venv\lib\site-packages\jinja2\environment.py", line 869, in get_or_select_template
    return self.get_template(template_name_or_list, parent, globals)
  File "c:\users\marks\local sites\mvr flask database\venv\lib\site-packages\jinja2\environment.py", line 830, in get_template
    return self._load_template(name, self.make_globals(globals))
  File "c:\users\marks\local sites\mvr flask database\venv\lib\site-packages\jinja2\environment.py", line 804, in _load_template
    template = self.loader.load(self, name, globals)
  File "c:\users\marks\local sites\mvr flask database\venv\lib\site-packages\jinja2\loaders.py", line 113, in load
    source, filename, uptodate = self.get_source(environment, name)
  File "c:\users\marks\local sites\mvr flask database\venv\lib\site-packages\flask\templating.py", line 58, in get_source
    return self._get_source_fast(environment, template)
  File "c:\users\marks\local sites\mvr flask database\venv\lib\site-packages\flask\templating.py", line 86, in _get_source_fast
    raise TemplateNotFound(template)
jinja2.exceptions.TemplateNotFound: newService.html.html
2020-03-10 12:22:35,248 INFO: MVR Database [in C:\Users\marks\Local Sites\MVR Flask Database\app\__init__.py:49]
2020-03-10 12:25:18,710 INFO: MVR Database [in C:\Users\marks\Local Sites\MVR Flask Database\app\__init__.py:49]
