2019-08-12 19:07:19,543 ERROR: Exception on /clinictable [GET] [in c:\users\mark\local sites\mvr database\mvr-database\venv\lib\site-packages\flask\app.py:1780]
Traceback (most recent call last):
  File "c:\users\mark\local sites\mvr database\mvr-database\venv\lib\site-packages\flask\app.py", line 2311, in wsgi_app
    response = self.full_dispatch_request()
  File "c:\users\mark\local sites\mvr database\mvr-database\venv\lib\site-packages\flask\app.py", line 1834, in full_dispatch_request
    rv = self.handle_user_exception(e)
  File "c:\users\mark\local sites\mvr database\mvr-database\venv\lib\site-packages\flask\app.py", line 1737, in handle_user_exception
    reraise(exc_type, exc_value, tb)
  File "c:\users\mark\local sites\mvr database\mvr-database\venv\lib\site-packages\flask\_compat.py", line 36, in reraise
    raise value
  File "c:\users\mark\local sites\mvr database\mvr-database\venv\lib\site-packages\flask\app.py", line 1832, in full_dispatch_request
    rv = self.dispatch_request()
  File "c:\users\mark\local sites\mvr database\mvr-database\venv\lib\site-packages\flask\app.py", line 1818, in dispatch_request
    return self.view_functions[rule.endpoint](**req.view_args)
  File "C:\Users\Mark\Local Sites\MVR database\MVR-Database\app\routes.py", line 152, in clinicTable
    return render_template('clinicTable.html',  title='All Clinics', clinics=clinics)
  File "c:\users\mark\local sites\mvr database\mvr-database\venv\lib\site-packages\flask\templating.py", line 134, in render_template
    return _render(ctx.app.jinja_env.get_or_select_template(template_name_or_list),
  File "c:\users\mark\local sites\mvr database\mvr-database\venv\lib\site-packages\jinja2\environment.py", line 869, in get_or_select_template
    return self.get_template(template_name_or_list, parent, globals)
  File "c:\users\mark\local sites\mvr database\mvr-database\venv\lib\site-packages\jinja2\environment.py", line 830, in get_template
    return self._load_template(name, self.make_globals(globals))
  File "c:\users\mark\local sites\mvr database\mvr-database\venv\lib\site-packages\jinja2\environment.py", line 804, in _load_template
    template = self.loader.load(self, name, globals)
  File "c:\users\mark\local sites\mvr database\mvr-database\venv\lib\site-packages\jinja2\loaders.py", line 125, in load
    code = environment.compile(source, name, filename)
  File "c:\users\mark\local sites\mvr database\mvr-database\venv\lib\site-packages\jinja2\environment.py", line 591, in compile
    self.handle_exception(exc_info, source_hint=source_hint)
  File "c:\users\mark\local sites\mvr database\mvr-database\venv\lib\site-packages\jinja2\environment.py", line 780, in handle_exception
    reraise(exc_type, exc_value, tb)
  File "c:\users\mark\local sites\mvr database\mvr-database\venv\lib\site-packages\jinja2\_compat.py", line 37, in reraise
    raise value.with_traceback(tb)
  File "C:\Users\Mark\Local Sites\MVR database\MVR-Database\app\templates\clinicTable.html", line 22, in template
    <p>{% 2+3 %}</p>
  File "c:\users\mark\local sites\mvr database\mvr-database\venv\lib\site-packages\jinja2\environment.py", line 497, in _parse
    return Parser(self, source, name, encode_filename(filename)).parse()
  File "c:\users\mark\local sites\mvr database\mvr-database\venv\lib\site-packages\jinja2\parser.py", line 901, in parse
    result = nodes.Template(self.subparse(), lineno=1)
  File "c:\users\mark\local sites\mvr database\mvr-database\venv\lib\site-packages\jinja2\parser.py", line 883, in subparse
    rv = self.parse_statement()
  File "c:\users\mark\local sites\mvr database\mvr-database\venv\lib\site-packages\jinja2\parser.py", line 130, in parse_statement
    return getattr(self, 'parse_' + self.stream.current.value)()
  File "c:\users\mark\local sites\mvr database\mvr-database\venv\lib\site-packages\jinja2\parser.py", line 268, in parse_block
    node.body = self.parse_statements(('name:endblock',), drop_needle=True)
  File "c:\users\mark\local sites\mvr database\mvr-database\venv\lib\site-packages\jinja2\parser.py", line 165, in parse_statements
    result = self.subparse(end_tokens)
  File "c:\users\mark\local sites\mvr database\mvr-database\venv\lib\site-packages\jinja2\parser.py", line 883, in subparse
    rv = self.parse_statement()
  File "c:\users\mark\local sites\mvr database\mvr-database\venv\lib\site-packages\jinja2\parser.py", line 125, in parse_statement
    self.fail('tag name expected', token.lineno)
  File "c:\users\mark\local sites\mvr database\mvr-database\venv\lib\site-packages\jinja2\parser.py", line 59, in fail
    raise exc(msg, lineno, self.name, self.filename)
jinja2.exceptions.TemplateSyntaxError: tag name expected
2019-08-12 19:08:42,232 INFO: MVR Database [in C:\Users\Mark\Local Sites\MVR database\MVR-Database\app\__init__.py:47]
2019-08-12 19:12:32,362 INFO: MVR Database [in C:\Users\Mark\Local Sites\MVR database\MVR-Database\app\__init__.py:47]
2019-08-13 12:09:08,581 INFO: MVR Database [in C:\Users\Mark\Local Sites\MVR database\MVR-Database\app\__init__.py:47]
2019-08-13 12:22:55,153 INFO: MVR Database [in C:\Users\Mark\Local Sites\MVR database\MVR-Database\app\__init__.py:47]
2019-08-13 12:49:53,101 INFO: MVR Database [in C:\Users\Mark\Local Sites\MVR database\MVR-Database\app\__init__.py:47]
2019-08-13 12:50:45,666 INFO: MVR Database [in C:\Users\Mark\Local Sites\MVR database\MVR-Database\app\__init__.py:47]
2019-08-13 12:50:57,498 ERROR: Exception on /newdoc [GET] [in c:\users\mark\local sites\mvr database\mvr-database\venv\lib\site-packages\flask\app.py:1780]
Traceback (most recent call last):
  File "c:\users\mark\local sites\mvr database\mvr-database\venv\lib\site-packages\flask\app.py", line 2311, in wsgi_app
    response = self.full_dispatch_request()
  File "c:\users\mark\local sites\mvr database\mvr-database\venv\lib\site-packages\flask\app.py", line 1834, in full_dispatch_request
    rv = self.handle_user_exception(e)
  File "c:\users\mark\local sites\mvr database\mvr-database\venv\lib\site-packages\flask\app.py", line 1737, in handle_user_exception
    reraise(exc_type, exc_value, tb)
  File "c:\users\mark\local sites\mvr database\mvr-database\venv\lib\site-packages\flask\_compat.py", line 36, in reraise
    raise value
  File "c:\users\mark\local sites\mvr database\mvr-database\venv\lib\site-packages\flask\app.py", line 1832, in full_dispatch_request
    rv = self.dispatch_request()
  File "c:\users\mark\local sites\mvr database\mvr-database\venv\lib\site-packages\flask\app.py", line 1818, in dispatch_request
    return self.view_functions[rule.endpoint](**req.view_args)
  File "C:\Users\Mark\Local Sites\MVR database\MVR-Database\app\routes.py", line 129, in newDoc
    form = newDoctor()
  File "c:\users\mark\local sites\mvr database\mvr-database\venv\lib\site-packages\wtforms\form.py", line 212, in __call__
    return type.__call__(cls, *args, **kwargs)
  File "c:\users\mark\local sites\mvr database\mvr-database\venv\lib\site-packages\flask_wtf\form.py", line 88, in __init__
    super(FlaskForm, self).__init__(formdata=formdata, **kwargs)
  File "c:\users\mark\local sites\mvr database\mvr-database\venv\lib\site-packages\wtforms\form.py", line 272, in __init__
    super(Form, self).__init__(self._unbound_fields, meta=meta_obj, prefix=prefix)
  File "c:\users\mark\local sites\mvr database\mvr-database\venv\lib\site-packages\wtforms\form.py", line 52, in __init__
    field = meta.bind_field(self, unbound_field, options)
  File "c:\users\mark\local sites\mvr database\mvr-database\venv\lib\site-packages\wtforms\meta.py", line 27, in bind_field
    return unbound_field.bind(form=form, **options)
  File "c:\users\mark\local sites\mvr database\mvr-database\venv\lib\site-packages\wtforms\fields\core.py", line 353, in bind
    return self.field_class(*self.args, **kw)
TypeError: __init__() got an unexpected keyword argument 'choices'
2019-08-13 12:51:19,267 INFO: MVR Database [in C:\Users\Mark\Local Sites\MVR database\MVR-Database\app\__init__.py:47]
2019-08-13 12:59:02,497 INFO: MVR Database [in C:\Users\Mark\Local Sites\MVR database\MVR-Database\app\__init__.py:47]
2019-08-13 12:59:12,694 ERROR: Exception on /newdoc [POST] [in c:\users\mark\local sites\mvr database\mvr-database\venv\lib\site-packages\flask\app.py:1780]
Traceback (most recent call last):
  File "c:\users\mark\local sites\mvr database\mvr-database\venv\lib\site-packages\flask\app.py", line 2311, in wsgi_app
    response = self.full_dispatch_request()
  File "c:\users\mark\local sites\mvr database\mvr-database\venv\lib\site-packages\flask\app.py", line 1834, in full_dispatch_request
    rv = self.handle_user_exception(e)
  File "c:\users\mark\local sites\mvr database\mvr-database\venv\lib\site-packages\flask\app.py", line 1737, in handle_user_exception
    reraise(exc_type, exc_value, tb)
  File "c:\users\mark\local sites\mvr database\mvr-database\venv\lib\site-packages\flask\_compat.py", line 36, in reraise
    raise value
  File "c:\users\mark\local sites\mvr database\mvr-database\venv\lib\site-packages\flask\app.py", line 1832, in full_dispatch_request
    rv = self.dispatch_request()
  File "c:\users\mark\local sites\mvr database\mvr-database\venv\lib\site-packages\flask\app.py", line 1818, in dispatch_request
    return self.view_functions[rule.endpoint](**req.view_args)
  File "C:\Users\Mark\Local Sites\MVR database\MVR-Database\app\routes.py", line 131, in newDoc
    doctor = Doctor(clinicName=form.clinic.data, clinicSerialNum=form.clinic.value, first=form.first.data, middle=form.middle.data, last=form.last.data, phone=form.phone.data, email=form.email.data, note=form.note.data, doctorSerialNum=randomStringDigits(8))
NameError: name 'Doctor' is not defined
2019-08-13 13:00:13,496 INFO: MVR Database [in C:\Users\Mark\Local Sites\MVR database\MVR-Database\app\__init__.py:47]
